Workbook
Name SegmentaciónDeDatos_Resumen_Vicente: #N/A

Sheet Resumen Por Acreedor
A2: Situación | B2: (Todas)
A4: Razón Social Acreedor | B4: Monto $
A5: Agrícola Ancalí Ltda | B5: 316
A6: Alto Cautín SpA | B6: 14950
A7: Andes Generación SpA | B7: 1431569
A8: CE CENTINELA SOLAR SPA | B8: 82570
A9: CE Uribe de Antofagasta Solar SpA | B9: 777616
A10: Central Cardones S.A. | B10: 5806845
A11: Central Colmito S.A. | B11: 27203199
A12: Central Yungay S.A. | B12: 37397764
A13: Chungungo S.A. | B13: 235199
A14: Chungungo Solar SpA | B14: 2897302
A15: CINERGIA Chile SpA | B15: 52742
A16: Colbún S.A. | B16: 110580829
... A94: Total general | B94: 514934265

Sheet TD
A1: Situación | B1: Abierta
F2: Situación | G2: Abierta
A3: Categoria | B3: Monto bruto | C3: Nemotécnico
A4: cierre solicitado | B4: 2466049 | C4: 2 | F4: Resumen | G4: Observación | H4: N°Disc | I4: Plazo | J4: Accion | K4: Monto bruto | L4: Recuento
A5: En Gestion | B5: 23127955 | C5: 31 | F5: cierre solicitado | G5: Con observacion | H5: DISC_327185 | I5: 16-09-2025 | J5: Se deja observacion para que refacturen exento de iva | K5: 1629820 | L5: 1
A6: Total general | B6: 25594004 | C6: 33 | H6: DISC_328372 | I6: 19-09-2025 | J6: Se deja observacion para que refacturen exento de iva | K6: 836229 | L6: 1
F7: Total cierre solicitado | K7: 2466049 | L7: 2
F8: En Gestion | G8: Coordinado Rechaza Cierre | H8: DISC_326204 | I8: 08-09-2025 | J8: se rechaza cierre por parte del coordinado, no puede emitir exento | K8: 137103 | L8: 1
H9: DISC_341053 | I9: 30-10-2025 | J9: se rechaza cierre por parte del coordinado, no se especifica que el cobro es exento | K9: 103544 | L9: 1
H10: DISC_341078 | I10: 30-10-2025 | J10: se rechaza cierre por parte del coordinado, no se especifica que el cobro es exento | K10: 613624 | L10: 1
H11: DISC_341100 | I11: 30-10-2025 | J11: se rechaza cierre por parte del coordinado, no se especifica que el cobro es exento | K11: 104546 | L11: 1
G12: Enviar a pago | H12: DISC_349676 | I12: 21-11-2025 | J12: enviar hes a la ale | K12: 411 | L12: 1
H13: DISC_349677 | I13: 21-11-2025 | J13: enviar hes a la ale | K13: 12171 | L13: 1
H14: DISC_349679 | I14: 21-11-2025 | J14: enviar hes a la ale | K14: 45 | L14: 1
G15: Nueva | H15: DISC_350902 | I15: 24-11-2025 | J15: Investigar | K15: 71 | L15: 1
H16: DISC_350903 | I16: 24-11-2025 | J16: Investigar | K16: 77 | L16: 1
H17: DISC_350904 | I17: 24-11-2025 | J17: Investigar | K17: 40 | L17: 1
H18: DISC_350905 | I18: 24-11-2025 | J18: Investigar | K18: 14 | L18: 1
H19: DISC_350972 | I19: 24-11-2025 | J19: Investigar | K19: 64393 | L19: 1
H20: DISC_351238 | I20: 25-11-2025 | J20: Investigar | K20: 13111749 | L20: 1
H21: DISC_353295 | I21: 01-12-2025 | J21: Investigar | K21: 282442 | L21: 1
H22: DISC_353298 | I22: 01-12-2025 | J22: Investigar | K22: 60640 | L22: 1
H23: DISC_353456 | I23: 01-12-2025 | J23: Investigar | K23: 71021 | L23: 1
H24: DISC_354762 | I24: 03-12-2025 | J24: Investigar | K24: 6251 | L24: 1
H25: DISC_354763 | I25: 03-12-2025 | J25: Investigar | K25: 196534 | L25: 1
H26: DISC_354764 | I26: 03-12-2025 | J26: Investigar | K26: 6346 | L26: 1
H27: DISC_354765 | I27: 03-12-2025 | J27: Investigar | K27: 6097 | L27: 1
... H38: DISC_356389 | I38: 08-12-2025 | J38: Investigar | K38: 1460770 | L38: 1
F39: Total En Gestion | K39: 23127955 | L39: 31
F40: Total general | K40: 25594004 | L40: 33

Sheet Datos
A1: Activity | B1: Estado de la tarea | C1: Fecha Creación del caso hasta | D1: Current User - Full Name | E1: Nemotécnico | F1: Rut Acreedor (malo) | G1: Razón Social Acreedor | H1: Rut Deudor 77316204-2 | I1: Razón Social Deudor | J1: Tipo de Disconformidad | K1: Monto bruto instrucción de pago | L1: Saldo Pendiente (Neto) | M1: Número de Disconformidad | N1: Fecha de Vencimiento Desde | O1: ¿Disconformidad Abierta por? | P1: Tipo de Disconformidad2 | Q1: En Espera de Ejecución | R1: Mes | S1: Plazo (10 Dias habiles [Columna C]) | T1: N° Acreedor | U1: N° factura | V1: Filtro Abiertas | W1: OC | X1: HES | Y1: Tiene oc y hes? Fecha lib | Z1: Observación (tiempo de gestion prom 7 MIN X Dis) | AA1: resposable | AB1: Situación | AC1: RUT ACREEDOR | AD1: Accion | AE1: Resumen Vicente
B2: Cerrado | C2: 45005.679 | E2: [DISC_38061][P][SEN_[TEE_][Oct22][L][V01]][4673965] | F2: 766165389 | G2: Innovación Energía S.A. | H2: 77316204 | I2: CGE COMERCIALIZADORA SPA | J2: Pago | K2: 201828 | L2: 201828 | M2: DISC_38061 | N2: 44902 | O2: Acreedor | P2: Pago | Q2: No | R2: =+MONTH(C2) | T2: 1025977 | AB2: Cerrada | AC2: =+VLOOKUP(T2,'BBDD ACREEDORES'!$B:$C,2,0) | AE2: =IF(AB2="Abierta",V2,"Cerrada")
B3: Cerrado | C3: 45033.743 | E3: [DISC_41718][P][SEN_[BP__][Sep22][L][V01]][4518794] | F3: 762037882 | G3: Andes Generación SpA | H3: 77316204 | I3: CGE COMERCIALIZADORA SPA | J3: Pago | K3: 30529 | L3: 30529 | M3: DISC_41718 | N3: 45037.413 | O3: Acreedor | P3: Pago | Q3: No | R3: =+MONTH(C3) | T3: 1021658 | AB3: Cerrada | AC3: =+VLOOKUP(T3,'BBDD ACREEDORES'!$B:$C,2,0) | AE3: =IF(AB3="Abierta",V3,"Cerrada")
B4: Cerrado | C4: 45051.631 | E4: [DISC_43630][P][SEN_[CUN_][Feb23][L][V01]][5318610] | F4: 767876904 | G4: Transmisora Eléctrica del Norte S.A. | H4: 77316204 | I4: CGE COMERCIALIZADORA SPA | J4: Pago | K4: 8613734 | L4: 8613734 | M4: DISC_43630 | N4: 45026 | O4: Acreedor | P4: Pago | Q4: No | R4: =+MONTH(C4) | T4: 1024418 | AB4: Cerrada | AC4: =+VLOOKUP(T4,'BBDD ACREEDORES'!$B:$C,2,0) | AE4: =IF(AB4="Abierta",V4,"Cerrada")
B5: Cerrado | C5: 45076.741 | E5: [DISC_47514][P][SEN_[TEE_][Ene23][L][V01]][5140524] | F5: 770606691 | G5: PFV Las Cachañas SpA | H5: 77316204 | I5: CGE COMERCIALIZADORA SPA | J5: Pago | K5: 99518 | L5: 99518 | M5: DISC_47514 | N5: 1/1/1753 12:00:00 AM | O5: Acreedor | P5: Pago | Q5: No | R5: =+MONTH(C5) | T5: 1027702 | AB5: Cerrada | AC5: =+VLOOKUP(T5,'BBDD ACREEDORES'!$B:$C,2,0) | AE5: =IF(AB5="Abierta",V5,"Cerrada")
B6: Cerrado | C6: 45079.408 | E6: [DISC_49354][P][SEN_[CUN_][Mar23][L][V01]][5402659] | F6: 767876904 | G6: Transmisora Eléctrica del Norte S.A. | H6: 77316204 | I6: CGE COMERCIALIZADORA SPA | J6: Pago | K6: 9395862 | L6: 9395862 | M6: DISC_49354 | N6: 45055 | O6: Acreedor | P6: Pago | Q6: No | R6: =+MONTH(C6) | T6: 1024418 | AB6: Cerrada | AC6: =+VLOOKUP(T6,'BBDD ACREEDORES'!$B:$C,2,0) | AE6: =IF(AB6="Abierta",V6,"Cerrada")
B7: Cerrado | C7: 45082.662 | E7: [DISC_51124][P][SEN_[BP__][Abr23][L][V01]][5433273] | F7: 760718912 | G7: Hidroelectrica Allipén S.A. | H7: 77316204 | I7: CGE COMERCIALIZADORA SPA | J7: Pago | K7: 2740 | L7: 2740 | M7: DISC_51124 | N7: 45086.331 | O7: Acreedor | P7: Pago | Q7: No | R7: =+MONTH(C7) | T7: 1015404 | AB7: Cerrada | AC7: =+VLOOKUP(T7,'BBDD ACREEDORES'!$B:$C,2,0) | AE7: =IF(AB7="Abierta",V7,"Cerrada")
B8: Cerrado | C8: 45082.662 | E8: [DISC_51125][P][SEN_[TEE_][Abr23][L][V01]][5466791] | F8: 760718912 | G8: Hidroelectrica Allipén S.A. | H8: 77316204 | I8: CGE COMERCIALIZADORA SPA | J8: Pago | K8: 104048 | L8: 104048 | M8: DISC_51125 | N8: 45086.332 | O8: Acreedor | P8: Pago | Q8: No | R8: =+MONTH(C8) | T8: 1015404 | AB8: Cerrada | AC8: =+VLOOKUP(T8,'BBDD ACREEDORES'!$B:$C,2,0) | AE8: =IF(AB8="Abierta",V8,"Cerrada")
B9: Cerrado | C9: 45082.687 | E9: [DISC_51219][P][SEN_[BP__][Abr23][L][V01]][5433447] | F9: 768340005 | G9: Hidroelectrica Trueno S.A. | H9: 77316204 | I9: CGE COMERCIALIZADORA SPA | J9: Pago | K9: 1505 | L9: 1505 | M9: DISC_51219 | N9: 45086.356 | O9: Acreedor | P9: Pago | Q9: No | R9: =+MONTH(C9) | T9: 1026449 | AB9: Cerrada | AC9: =+VLOOKUP(T9,'BBDD ACREEDORES'!$B:$C,2,0) | AE9: =IF(AB9="Abierta",V9,"Cerrada")
B10: Cerrado | C10: 45082.703 | E10: [DISC_51261][P][SEN_[BP__][Abr23][L][V01]][5433607] | F10: 995896206 | G10: Hidroelectrica Puclaro S.A. | H10: 77316204 | I10: CGE COMERCIALIZADORA SPA | J10: Pago | K10: 6255 | L10: 6255 | M10: DISC_51261 | N10: 45086.372 | O10: Acreedor | P10: Pago | Q10: No | R10: =+MONTH(C10) | T10: 1014010 | AB10: Cerrada | AC10: =+VLOOKUP(T10,'BBDD ACREEDORES'!$B:$C,2,0) | AE10: =IF(AB10="Abierta",V10,"Cerrada")
B11: Cerrado | C11: 45082.703 | E11: [DISC_51262][P][SEN_[TEE_][Abr23][L][V01]][5467130] | F11: 995896206 | G11: Hidroelectrica Puclaro S.A. | H11: 77316204 | I11: CGE COMERCIALIZADORA SPA | J11: Pago | K11: 37312 | L11: 37312 | M11: DISC_51262 | N11: 45086.372 | O11: Acreedor | P11: Pago | Q11: No | R11: =+MONTH(C11) | T11: 1014010 | AB11: Cerrada | AC11: =+VLOOKUP(T11,'BBDD ACREEDORES'!$B:$C,2,0) | AE11: =IF(AB11="Abierta",V11,"Cerrada")
B12: Cerrado | C12: 45083.372 | E12: [DISC_51458][P][SEN_[BP__][Abr23][L][V01]][5433518] | F12: 760551368 | G12: Hidroeléctrica Mallarauco S.A. | H12: 77316204 | I12: CGE COMERCIALIZADORA SPA | J12: Pago | K12: 3780 | L12: 3780 | M12: DISC_51458 | N12: 45089.041 | O12: Acreedor | P12: Pago | Q12: No | R12: =+MONTH(C12) | T12: 1021439 | AB12: Cerrada | AC12: =+VLOOKUP(T12,'BBDD ACREEDORES'!$B:$C,2,0) | AE12: =IF(AB12="Abierta",V12,"Cerrada")
B13: Cerrado | C13: 45083.372 | E13: [DISC_51459][P][SEN_[TEE_][Abr23][L][V01]][5467039] | F13: 760551368 | G13: Hidroeléctrica Mallarauco S.A. | H13: 77316204 | I13: CGE COMERCIALIZADORA SPA | J13: Pago | K13: 6320 | L13: 6320 | M13: DISC_51459 | N13: 45089.042 | O13: Acreedor | P13: Pago | Q13: No | R13: =+MONTH(C13) | T13: 1021439 | AB13: Cerrada | AC13: =+VLOOKUP(T13,'BBDD ACREEDORES'!$B:$C,2,0) | AE13: =IF(AB13="Abierta",V13,"Cerrada")
B14: Cerrado | C14: 45083.401 | E14: [DISC_51522][P][SEN_[BP__][Abr23][L][V01]][5433635] | F14: 760711136 | G14: Hidroeléctrica Río Huasco S.A. | H14: 77316204 | I14: CGE COMERCIALIZADORA SPA | J14: Pago | K14: 6361 | L14: 6361 | M14: DISC_51522 | N14: 45089.07 | O14: Acreedor | P14: Pago | Q14: No | R14: =+MONTH(C14) | T14: 1016827 | AB14: Cerrada | AC14: =+VLOOKUP(T14,'BBDD ACREEDORES'!$B:$C,2,0) | AE14: =IF(AB14="Abierta",V14,"Cerrada")
B15: Cerrado | C15: 45083.401 | E15: [DISC_51523][P][SEN_[TEE_][Abr23][L][V01]][5467158] | F15: 760711136 | G15: Hidroeléctrica Río Huasco S.A. | H15: 77316204 | I15: CGE COMERCIALIZADORA SPA | J15: Pago | K15: 51690 | L15: 51690 | M15: DISC_51523 | N15: 45089.071 | O15: Acreedor | P15: Pago | Q15: No | R15: =+MONTH(C15) | T15: 1016827 | AB15: Cerrada | AC15: =+VLOOKUP(T15,'BBDD ACREEDORES'!$B:$C,2,0) | AE15: =IF(AB15="Abierta",V15,"Cerrada")
B16: Cerrado | C16: 45083.464 | E16: [DISC_51843][P][SEN_[BP__][Abr23][L][V01]][5433374] | F16: 762640252 | G16: Hidroeléctrica Embalse Ancoa SpA | H16: 77316204 | I16: CGE COMERCIALIZADORA SPA | J16: Pago | K16: 7389 | L16: 7389 | M16: DISC_51843 | N16: 45089.133 | O16: Acreedor | P16: Pago | Q16: No | R16: =+MONTH(C16) | T16: 1023872 | AB16: Cerrada | AC16: =+VLOOKUP(T16,'BBDD ACREEDORES'!$B:$C,2,0) | AE16: =IF(AB16="Abierta",V16,"Cerrada")
B17: Cerrado | C17: 45083.464 | E17: [DISC_51844][P][SEN_[TEE_][Abr23][L][V01]][5466896] | F17: 762640252 | G17: Hidroeléctrica Embalse Ancoa SpA | H17: 77316204 | I17: CGE COMERCIALIZADORA SPA | J17: Pago | K17: 145700 | L17: 145700 | M17: DISC_51844 | N17: 45089.134 | O17: Acreedor | P17: Pago | Q17: No | R17: =+MONTH(C17) | T17: 1023872 | AB17: Cerrada | AC17: =+VLOOKUP(T17,'BBDD ACREEDORES'!$B:$C,2,0) | AE17: =IF(AB17="Abierta",V17,"Cerrada")
... B31: Cerrado | C31: 45091.725 | E31: [DISC_53382][P][SEN_[SCRT][Abr23][L][V01]][5491094] | F31: 760093289 | G31: Enlasa Generación Chile S.A. | H31: 77316204 | I31: CGE COMERCIALIZADORA SPA | J31: Pago | K31: 252546 | L31: 252546 | M31: DISC_53382 | N31: 45078 | O31: Acreedor | P31: Pago | Q31: No | R31: =+MONTH(C31) | T31: 1007718 | AB31: Cerrada | AC31: =+VLOOKUP(T31,'BBDD ACREEDORES'!$B:$C,2,0) | AE31: =IF(AB31="Abierta",V31,"Cerrada")
A32: Gestión de Cierre Disconformidad - Espera Resolución Cierre - Cierre Anticipado - Seguimiento Acreedor - Seguimiento Deudor - CANCELAR | B32: Cerrado | C32: 45091.753 | D32: - Sin Asignar - Pablo Montero - Paola Ahumada - Usuario Pivot | E32: [DISC_53392][P][SEN_[TEE_][Abr23][L][V01]][5466991] | F32: 760370363 | G32: Empresa Eléctrica La Arena SpA | H32: 77316204 | I32: CGE COMERCIALIZADORA SPA | J32: Pago | K32: 119249 | L32: 119249 | M32: DISC_53392 | N32: 45097.423 | O32: Acreedor | P32: Pago | Q32: No | R32: =+MONTH(C32) | S32: =+C32+14 | T32: 1014070 | U32: 10466 | W32: Pagado 29/6 | AB32: Cerrada | AC32: =+VLOOKUP(T32,'BBDD ACREEDORES'!$B:$C,2,0) | AE32: =IF(AB32="Abierta",V32,"Cerrada")
A33: Gestión de Cierre Disconformidad - Espera Resolución Cierre - Seguimiento Deudor - Cierre Anticipado - Seguimiento Acreedor - CANCELAR | B33: Cerrado | C33: 45091.754 | D33: - Sin Asignar - Usuario Pivot | E33: [DISC_53395][P][SEN_[BP__][Abr23][L][V01]][5433470] | F33: 760370363 | G33: Empresa Eléctrica La Arena SpA | H33: 77316204 | I33: CGE COMERCIALIZADORA SPA | J33: Pago | K33: 3560 | L33: 3560 | M33: DISC_53395 | N33: 45097.423 | O33: Acreedor | P33: Pago | Q33: No | R33: =+MONTH(C33) | S33: =+C33+14 | T33: 1014070 | U33: 10550 | W33: Pagado 29/6 | AB33: Cerrada | AC33: =+VLOOKUP(T33,'BBDD ACREEDORES'!$B:$C,2,0) | AE33: =IF(AB33="Abierta",V33,"Cerrada")
A34: Cierre Anticipado - Seguimiento Acreedor - Seguimiento Deudor - Espera Movimientos - Espera Ejecución en P. de Garantías - CANCELAR | B34: Cerrado | C34: 45091.768 | D34: Sin Asignar - Paola Ahumada - Usuario Pivot | E34: [DISC_53411][P][SEN_[TEE_][Abr23][L][V01]][5466884] | F34: 763622681 | G34: Empresa Eléctrica Tranquil S.P.A | H34: 77316204 | I34: CGE COMERCIALIZADORA SPA | J34: Pago | K34: 33515 | L34: 33515 | M34: DISC_53411 | N34: 45097.437 | O34: Acreedor | P34: Pago | Q34: Si | R34: =+MONTH(C34) | T34: 1023007 | U34: 10434 | W34: Pagado 29/6 | AB34: Cerrada | AC34: =+VLOOKUP(T34,'BBDD ACREEDORES'!$B:$C,2,0) | AE34: =IF(AB34="Abierta",V34,"Cerrada")
A35: Gestión de Cierre Disconformidad - Espera Resolución Cierre - Seguimiento Deudor - Cierre Anticipado - Seguimiento Acreedor - CANCELAR | B35: Cerrado | C35: 45091.768 | D35: - Sin Asignar - Usuario Pivot | E35: [DISC_53412][P][SEN_[BP__][Abr23][L][V01]][5433360] | F35: 763622681 | G35: Empresa Eléctrica Tranquil S.P.A | H35: 77316204 | I35: CGE COMERCIALIZADORA SPA | J35: Pago | K35: 2353 | L35: 2353 | M35: DISC_53412 | N35: 45097.437 | O35: Acreedor | P35: Pago | Q35: No | R35: =+MONTH(C35) | S35: =+C35+14 | T35: 1023007 | U35: 10517 | W35: Pagado 29/6 | AB35: Cerrada | AC35: =+VLOOKUP(T35,'BBDD ACREEDORES'!$B:$C,2,0) | AE35: =IF(AB35="Abierta",V35,"Cerrada")
B36: Cerrado | C36: 45092.457 | E36: [DISC_53459][P][SEN_[BP__][Abr23][L][V01]][5433538] | F36: 762652870 | G36: Generación de Energía Nueva Degan SpA | H36: 77316204 | I36: CGE COMERCIALIZADORA SPA | J36: Pago | K36: 64841 | L36: 64841 | M36: DISC_53459 | N36: 45098.126 | O36: Acreedor | P36: Pago | Q36: No | R36: =+MONTH(C36) | T36: 1016242 | AB36: Cerrada | AC36: =+VLOOKUP(T36,'BBDD ACREEDORES'!$B:$C,2,0) | AE36: =IF(AB36="Abierta",V36,"Cerrada")
B37: Cerrado | C37: 45092.457 | E37: [DISC_53460][P][SEN_[TEE_][Abr23][L][V01]][5467060] | F37: 762652870 | G37: Generación de Energía Nueva Degan SpA | H37: 77316204 | I37: CGE COMERCIALIZADORA SPA | J37: Pago | K37: 14738 | L37: 14738 | M37: DISC_53460 | N37: 45098.126 | O37: Acreedor | P37: Pago | Q37: No | R37: =+MONTH(C37) | T37: 1016242 | AB37: Cerrada | AC37: =+VLOOKUP(T37,'BBDD ACREEDORES'!$B:$C,2,0) | AE37: =IF(AB37="Abierta",V37,"Cerrada")
B38: Cerrado | C38: 45092.488 | E38: [DISC_53504][P][SEN_[BP__][Abr23][L][V01]][5433282] | F38: 76009904k | G38: Generadora Antilhue Spa | H38: 77316204 | I38: CGE COMERCIALIZADORA SPA | J38: Pago | K38: 120144 | L38: 120144 | M38: DISC_53504 | N38: 45098.157 | O38: Acreedor | P38: Pago | Q38: No | R38: =+MONTH(C38) | T38: 1025760 | AB38: Cerrada | AC38: =+VLOOKUP(T38,'BBDD ACREEDORES'!$B:$C,2,0) | AE38: =IF(AB38="Abierta",V38,"Cerrada")
B39: Cerrado | C39: 45092.488 | E39: [DISC_53505][P][SEN_[SCRT][Abr23][L][V01]][5491088] | F39: 76009904k | G39: Generadora Antilhue Spa | H39: 77316204 | I39: CGE COMERCIALIZADORA SPA | J39: Pago | K39: 260324 | L39: 260324 | M39: DISC_53505 | N39: 45098.157 | O39: Acreedor | P39: Pago | Q39: No | R39: =+MONTH(C39) | T39: 1025760 | AB39: Cerrada | AC39: =+VLOOKUP(T39,'BBDD ACREEDORES'!$B:$C,2,0) | AE39: =IF(AB39="Abierta",V39,"Cerrada")
B40: Cerrado | C40: 45092.488 | E40: [DISC_53506][P][SEN_[TEE_][Abr23][L][V01]][5466801] | F40: 76009904k | G40: Generadora Antilhue Spa | H40: 77316204 | I40: CGE COMERCIALIZADORA SPA | J40: Pago | K40: 364752 | L40: 364752 | M40: DISC_53506 | N40: 45098.158 | O40: Acreedor | P40: Pago | Q40: No | R40: =+MONTH(C40) | T40: 1025760 | AB40: Cerrada | AC40: =+VLOOKUP(T40,'BBDD ACREEDORES'!$B:$C,2,0) | AE40: =IF(AB40="Abierta",V40,"Cerrada")
B41: Cerrado | C41: 45092.507 | E41: [DISC_53529][P][SEN_[TEE_][Abr23][L][V01]][5466983] | F41: 772529457 | G41: Inversiones Chacabuco SpA | H41: 77316204 | I41: CGE COMERCIALIZADORA SPA | J41: Pago | K41: 126266 | L41: 126266 | M41: DISC_53529 | N41: 45098.176 | O41: Acreedor | P41: Pago | Q41: No | R41: =+MONTH(C41) | T41: 1026424 | AB41: Cerrada | AC41: =+VLOOKUP(T41,'BBDD ACREEDORES'!$B:$C,2,0) | AE41: =IF(AB41="Abierta",V41,"Cerrada")
B42: Cerrado | C42: 45092.507 | E42: [DISC_53530][P][SEN_[BP__][Abr23][L][V01]][5433464] | F42: 772529457 | G42: Inversiones Chacabuco SpA | H42: 77316204 | I42: CGE COMERCIALIZADORA SPA | J42: Pago | K42: 3308 | L42: 3308 | M42: DISC_53530 | N42: 45098.176 | O42: Acreedor | P42: Pago | Q42: No | R42: =+MONTH(C42) | T42: 1026424 | AB42: Cerrada | AC42: =+VLOOKUP(T42,'BBDD ACREEDORES'!$B:$C,2,0) | AE42: =IF(AB42="Abierta",V42,"Cerrada")
B43: Cerrado | C43: 45092.555 | E43: [DISC_53551][P][SEN_[BP__][Abr23][L][V01]][5433664] | F43: 772619561 | G43: Solar la Blanquina SpA | H43: 77316204 | I43: CGE COMERCIALIZADORA SPA | J43: Pago | K43: 3098 | L43: 3098 | M43: DISC_53551 | N43: 45098.224 | O43: Acreedor | P43: Pago | Q43: No | R43: =+MONTH(C43) | T43: 1026425 | AB43: Cerrada | AC43: =+VLOOKUP(T43,'BBDD ACREEDORES'!$B:$C,2,0) | AE43: =IF(AB43="Abierta",V43,"Cerrada")
B44: Cerrado | C44: 45092.555 | E44: [DISC_53552][P][SEN_[TEE_][Abr23][L][V01]][5467185] | F44: 772619561 | G44: Solar la Blanquina SpA | H44: 77316204 | I44: CGE COMERCIALIZADORA SPA | J44: Pago | K44: 78897 | L44: 78897 | M44: DISC_53552 | N44: 45098.225 | O44: Acreedor | P44: Pago | Q44: No | R44: =+MONTH(C44) | T44: 1026425 | AB44: Cerrada | AC44: =+VLOOKUP(T44,'BBDD ACREEDORES'!$B:$C,2,0) | AE44: =IF(AB44="Abierta",V44,"Cerrada")
B45: Cerrado | C45: 45092.585 | E45: [DISC_53578][P][SEN_[BP__][Abr23][L][V01]][5433399] | F45: 770420326 | G45: Fontus Prime Solar SpA | H45: 77316204 | I45: CGE COMERCIALIZADORA SPA | J45: Pago | K45: 25821 | L45: 25821 | M45: DISC_53578 | N45: 45098.254 | O45: Acreedor | P45: Pago | Q45: No | R45: =+MONTH(C45) | T45: 1027439 | AB45: Cerrada | AC45: =+VLOOKUP(T45,'BBDD ACREEDORES'!$B:$C,2,0) | AE45: =IF(AB45="Abierta",V45,"Cerrada")
B46: Cerrado | C46: 45092.585 | E46: [DISC_53579][P][SEN_[TEE_][Abr23][L][V01]][5466918] | F46: 770420326 | G46: Fontus Prime Solar SpA | H46: 77316204 | I46: CGE COMERCIALIZADORA SPA | J46: Pago | K46: 968613 | L46: 968613 | M46: DISC_53579 | N46: 45098.254 | O46: Acreedor | P46: Pago | Q46: No | R46: =+MONTH(C46) | T46: 1027439 | AB46: Cerrada | AC46: =+VLOOKUP(T46,'BBDD ACREEDORES'!$B:$C,2,0) | AE46: =IF(AB46="Abierta",V46,"Cerrada")
B47: Cerrado | C47: 45092.658 | E47: [DISC_53616][P][SEN_[BP__][Abr23][L][V01]][5433421] | F47: 760103675 | G47: Generadora del Pacifico SpA | H47: 77316204 | I47: CGE COMERCIALIZADORA SPA | J47: Pago | K47: 147886 | L47: 147886 | M47: DISC_53616 | N47: 45098.328 | O47: Acreedor | P47: Pago | Q47: No | R47: =+MONTH(C47) | T47: 1008148 | AB47: Cerrada | AC47: =+VLOOKUP(T47,'BBDD ACREEDORES'!$B:$C,2,0) | AE47: =IF(AB47="Abierta",V47,"Cerrada")
B48: Cerrado | C48: 45092.658 | E48: [DISC_53617][P][SEN_[TEE_][Abr23][L][V01]][5466938] | F48: 760103675 | G48: Generadora del Pacifico SpA | H48: 77316204 | I48: CGE COMERCIALIZADORA SPA | J48: Pago | K48: 138297 | L48: 138297 | M48: DISC_53617 | N48: 45098.328 | O48: Acreedor | P48: Pago | Q48: No | R48: =+MONTH(C48) | T48: 1008148 | AB48: Cerrada | AC48: =+VLOOKUP(T48,'BBDD ACREEDORES'!$B:$C,2,0) | AE48: =IF(AB48="Abierta",V48,"Cerrada")
B49: Cerrado | C49: 45092.691 | E49: [DISC_53655][P][SEN_[BP__][Abr23][L][V01]][5433624] | F49: 764520556 | G49: Prime Energía Quickstart SpA | H49: 77316204 | I49: CGE COMERCIALIZADORA SPA | J49: Pago | K49: 710353 | L49: 710353 | M49: DISC_53655 | N49: 45098.361 | O49: Acreedor | P49: Pago | Q49: No | R49: =+MONTH(C49) | T49: 1026410 | AB49: Cerrada | AC49: =+VLOOKUP(T49,'BBDD ACREEDORES'!$B:$C,2,0) | AE49: =IF(AB49="Abierta",V49,"Cerrada")
B50: Cerrado | C50: 45092.691 | E50: [DISC_53656][P][SEN_[TEE_][Abr23][L][V01]][5467146] | F50: 764520556 | G50: Prime Energía Quickstart SpA | H50: 77316204 | I50: CGE COMERCIALIZADORA SPA | J50: Pago | K50: 103703 | L50: 103703 | M50: DISC_53656 | N50: 45098.361 | O50: Acreedor | P50: Pago | Q50: No | R50: =+MONTH(C50) | T50: 1026410 | AB50: Cerrada | AC50: =+VLOOKUP(T50,'BBDD ACREEDORES'!$B:$C,2,0) | AE50: =IF(AB50="Abierta",V50,"Cerrada")
B51: Cerrado | C51: 45093.459 | E51: [DISC_53779][P][SEN_[BP__][Abr23][L][V01]][5433274] | F51: 760441295 | G51: Alto Cautín SpA | H51: 77316204 | I51: CGE COMERCIALIZADORA SPA | J51: Pago | K51: 7487 | L51: 7487 | M51: DISC_53779 | N51: 45078 | O51: Acreedor | P51: Pago | Q51: No | R51: =+MONTH(C51) | T51: 1025979 | AB51: Cerrada | AC51: =+VLOOKUP(T51,'BBDD ACREEDORES'!$B:$C,2,0) | AE51: =IF(AB51="Abierta",V51,"Cerrada")
B52: Cerrado | C52: 45093.482 | E52: [DISC_53791][P][SEN_[TEE_][Abr23][L][V01]][5466911] | F52: 769258000 | G52: ESPINOS S.A. | H52: 77316204 | I52: CGE COMERCIALIZADORA SPA | J52: Pago | K52: 604896 | L52: 604896 | M52: DISC_53791 | N52: 45078 | O52: Acreedor | P52: Pago | Q52: No | R52: =+MONTH(C52) | T52: 1007707 | AB52: Cerrada | AC52: =+VLOOKUP(T52,'BBDD ACREEDORES'!$B:$C,2,0) | AE52: =IF(AB52="Abierta",V52,"Cerrada")
B53: Cerrado | C53: 45093.483 | E53: [DISC_53792][P][SEN_[BP__][Abr23][L][V01]][5433392] | F53: 769258000 | G53: ESPINOS S.A. | H53: 77316204 | I53: CGE COMERCIALIZADORA SPA | J53: Pago | K53: 331669 | L53: 331669 | M53: DISC_53792 | N53: 45078 | O53: Acreedor | P53: Pago | Q53: No | R53: =+MONTH(C53) | T53: 1007707 | AB53: Cerrada | AC53: =+VLOOKUP(T53,'BBDD ACREEDORES'!$B:$C,2,0) | AE53: =IF(AB53="Abierta",V53,"Cerrada")
...

Sheet BBDD ACREEDORES
A1: Razón Social Acreedor | B1: num acreedor | C1: RUT | D1: rut sin - | F1: 77.316.204-2 | G1: 77316204
A2: Innovación Energía S.A. | B2: 1025977 | C2: 76616538-9 | D2: =IFERROR(LEFT(C2,FIND("-",C2)-1),"")
A3: Andes Generación SpA | B3: 1021658 | C3: 76203788-2 | D3: =IFERROR(LEFT(C3,FIND("-",C3)-1),"")
A4: Transmisora Eléctrica del Norte S.A. | B4: 1024418 | C4: 76787690-4 | D4: =IFERROR(LEFT(C4,FIND("-",C4)-1),"")
A5: PFV Las Cachañas SpA | B5: 1027702 | D5: =IFERROR(LEFT(C5,FIND("-",C5)-1),"")
A6: Hidroelectrica Allipén S.A. | B6: 1015404 | C6: 76071891-2 | D6: =IFERROR(LEFT(C6,FIND("-",C6)-1),"")
A7: Hidroelectrica Trueno S.A. | B7: 1026449 | D7: =IFERROR(LEFT(C7,FIND("-",C7)-1),"")
A8: Hidroelectrica Puclaro S.A. | B8: 1014010 | D8: =IFERROR(LEFT(C8,FIND("-",C8)-1),"")
A9: Hidroeléctrica Mallarauco S.A. | B9: 1021439 | C9: 76055136-8 | D9: =IFERROR(LEFT(C9,FIND("-",C9)-1),"")
A10: Hidroeléctrica Río Huasco S.A. | B10: 1016827 | C10: 76071113-6 | D10: =IFERROR(LEFT(C10,FIND("-",C10)-1),"")
A11: Hidroeléctrica Embalse Ancoa SpA | B11: 1023872 | D11: =IFERROR(LEFT(C11,FIND("-",C11)-1),"")
A12: Hidroeléctrica Río Colorado S.A. | B12: 1023458 | D12: =IFERROR(LEFT(C12,FIND("-",C12)-1),"")
A13: Energía Pacífico S.A. | B13: 1013736 | C13: 76004531-4 | D13: =IFERROR(LEFT(C13,FIND("-",C13)-1),"")
A14: Colbún S.A. | B14: 1006828 | D14: =IFERROR(LEFT(C14,FIND("-",C14)-1),"")
A15: Central Yungay S.A. | B15: 1015580 | C15: 76060441-0 | D15: =IFERROR(LEFT(C15,FIND("-",C15)-1),"")
A16: Central Colmito S.A. | B16: 1020453 | C16: 76326949-3 | D16: =IFERROR(LEFT(C16,FIND("-",C16)-1),"")
A17: Enlasa Generación Chile S.A. | B17: 1007718 | C17: 76009328-9 | D17: =IFERROR(LEFT(C17,FIND("-",C17)-1),"")
A18: Chungungo Solar SpA | B18: 1026222 | C18: 76866361-0 | D18: =IFERROR(LEFT(C18,FIND("-",C18)-1),"")
A19: Empresa Eléctrica Diego de Almagro SpA | B19: 1008987 | C19: 76004337-0 | D19: =IFERROR(LEFT(C19,FIND("-",C19)-1),"")
A20: Empresa Eléctrica La Arena SpA | B20: 1014070 | C20: 76037036-3 | D20: =IFERROR(LEFT(C20,FIND("-",C20)-1),"")
A21: Empresa Eléctrica Tranquil S.P.A | B21: 1023007 | D21: =IFERROR(LEFT(C21,FIND("-",C21)-1),"")
A22: Generación de Energía Nueva Degan SpA | B22: 1016242 | C22: 76265287-0 | D22: =IFERROR(LEFT(C22,FIND("-",C22)-1),"")
A23: Generadora Antilhue Spa | B23: 1025760 | C23: 76009904-K | D23: =IFERROR(LEFT(C23,FIND("-",C23)-1),"")
A24: Inversiones Chacabuco SpA | B24: 1026424 | C24: 77252945-7 | D24: =IFERROR(LEFT(C24,FIND("-",C24)-1),"")
A25: Solar la Blanquina SpA | B25: 1026425 | C25: 77261956-1 | D25: =IFERROR(LEFT(C25,FIND("-",C25)-1),"")
A26: Fontus Prime Solar SpA | B26: 1027439 | C26: 77042032-6 | D26: =IFERROR(LEFT(C26,FIND("-",C26)-1),"")
A27: Generadora del Pacifico SpA | B27: 1008148 | C27: 76010367-5 | D27: =IFERROR(LEFT(C27,FIND("-",C27)-1),"")
A28: Prime Energía Quickstart SpA | B28: 1026410 | C28: 76452055-6 | D28: =IFERROR(LEFT(C28,FIND("-",C28)-1),"")
A29: Alto Cautín SpA | B29: 1025979 | D29: =IFERROR(LEFT(C29,FIND("-",C29)-1),"")
A30: ESPINOS S.A. | B30: 1007707 | D30: =IFERROR(LEFT(C30,FIND("-",C30)-1),"")
A31: SOCIEDAD GENERADORA AUSTRAL S.A. | B31: 1007708 | D31: =IFERROR(LEFT(C31,FIND("-",C31)-1),"")
A32: Enap Refinerias S.A. | B32: 1008529 | D32: =IFERROR(LEFT(C32,FIND("-",C32)-1),"")
A33: Sonnedix Parque Eólico El Arrayán SpA | B33: 1017381 | D33: =IFERROR(LEFT(C33,FIND("-",C33)-1),"")
A34: Electrica Nueva Energía S.A. | B34: 1007717 | C34: 76045612-8 | D34: =IFERROR(LEFT(C34,FIND("-",C34)-1),"")
A35: Central Cardones S.A. | B35: 1010018 | C35: 76550580-1 | D35: =IFERROR(LEFT(C35,FIND("-",C35)-1),"")
A36: SISTEMA DE TRANSMISIÓN DEL NORTE S.A. | B36: 1025221 | C36: 76410374-2 | D36: =IFERROR(LEFT(C36,FIND("-",C36)-1),"")
A37: Energía Atacama S.A. | B37: 1018350 | D37: =IFERROR(LEFT(C37,FIND("-",C37)-1),"")
A38: Sonnedix Energy Trading Chile SpA | B38: 1026655 | C38: 77257713-3 | D38: =IFERROR(LEFT(C38,FIND("-",C38)-1),"")
A39: Ibereólica Cabo Leones II S.A. | B39: 1025180 | C39: 76202178-1 | D39: =IFERROR(LEFT(C39,FIND("-",C39)-1),"")
A40: PARQUE SOLAR H6 | B40: 1025825 | D40: =IFERROR(LEFT(C40,FIND("-",C40)-1),"")
...

Sheet Consultas ALE
A1: Activity | B1: Estado de la tarea | C1: Fecha Creación del caso hasta | D1: Current User - Full Name | E1: Nemotécnico | F1: Rut Acreedor | G1: Razón Social Acreedor | H1: Rut Deudor | I1: Razón Social Deudor | J1: Tipo de Disconformidad | K1: Monto bruto instrucción de pago | L1: Saldo Pendiente (Neto) | M1: Número de Disconformidad | N1: Fecha de Vencimiento Desde | O1: ¿Disconformidad Abierta por? | P1: Tipo de Disconformidad | Q1: En Espera de Ejecución | R1: Mes | S1: Plazo (10 Dias hab) | T1: N° Acreedor | U1: N° factura | V1: Emisión | W1: OC | X1: HES
A2: Esperar Para Avanzar - Realizar Seguimiento Deudor - Realizar Seguimiento Acreedor - Cerrar Anticipado - Gestionar en Plazo de Regulación - Cancelar - Esperar Movimientos | B2: A tiempo - A tiempo - A tiempo - A tiempo - En riesgo - A tiempo - A tiempo | C2: 45970.098 | D2: - Sin Asignar | E2: [DISC_349677][P][SEN_[TEE_][May24][L][V01]][7626493] | F2: 77271459 | G2: ALTO BELLAVISTA SPA | H2: 77316204 | I2: CGE COMERCIALIZADORA SPA | J2: Pago | K2: 12171 | L2: 10228 | M2: DISC_349677 | N2: 45980.458 | O2: 45785 | P2: Acreedor | Q2: TEE_ | R2: =+MONTH(C2) | S2: =WORKDAY(C2,10) | T2: =+_xlfn.XLOOKUP(G2,'BBDD ACREEDORES'!$A:$A,'BBDD ACREEDORES'!$B:$B,"",0,1) | U2: 3395 | V2: En Gestion | W2: 41987220 | X2: 1003161596 | Z2: Enviadas a ingreso a pago | AA2: Ale | AB2: Abierta | AC2: =+VLOOKUP(T2,'BBDD ACREEDORES'!$B:$C,2,0)
A24: Razón Social Acreedor | B24: Monto bruto instrucción de pago | C24: Saldo Pendiente (Neto) | D24: Número de Disconformidad | E24: N° Acreedor | F24: N° factura | G24: Rut | H24: OC/HES | I24: OC | J24: HES
A25: =+G2 | B25: =K2 | C25: =+L2 | D25: =+M2 | E25: =+T2 | F25: =+U2 | G25: =+VLOOKUP(T2,'BBDD ACREEDORES'!$B:$C,2,0) | H25: =+N2 | I25: =+W2 | J25: =+X2
A26: =+G3 | B26: =K3 | C26: =+L3 | D26: =+M3 | E26: =+T3 | F26: =+U3 | G26: =+VLOOKUP(T3,'BBDD ACREEDORES'!$B:$C,2,0) | H26: =+N3 | I26: =+W3 | J26: =+X3 | K26: =+_xlfn.XLOOKUP(I26,'BBDD ACREEDORES'!$D:$D,'BBDD ACREEDORES'!C:C,"",0,1)
A27: =+G4 | B27: =K4 | C27: =+L4 | D27: =+M4 | E27: =+T4 | F27: =+U4 | G27: =+VLOOKUP(T4,'BBDD ACREEDORES'!$B:$C,2,0) | H27: =+N4 | I27: =+W4 | J27: =+X4 | K27: =+_xlfn.XLOOKUP(I27,'BBDD ACREEDORES'!$D:$D,'BBDD ACREEDORES'!C:C,"",0,1)
A28: =+G5 | B28: =K5 | C28: =+L5 | D28: =+M5 | E28: =+T5 | F28: =+U5 | G28: =+VLOOKUP(T5,'BBDD ACREEDORES'!$B:$C,2,0) | H28: =+N5 | I28: =+W5 | J28: =+X5 | K28: =+_xlfn.XLOOKUP(I28,'BBDD ACREEDORES'!$D:$D,'BBDD ACREEDORES'!C:C,"",0,1)
A29: =+G6 | B29: =K6 | C29: =+L6 | D29: =+M6 | E29: =+T6 | F29: =+U6 | G29: =+VLOOKUP(T6,'BBDD ACREEDORES'!$B:$C,2,0) | H29: =+N6 | I29: =+W6 | J29: =+X6
A30: =+G7 | B30: =K7 | C30: =+L7 | D30: =+M7 | E30: =+T7 | F30: =+U7 | G30: =+VLOOKUP(T7,'BBDD ACREEDORES'!$B:$C,2,0) | H30: =+N7 | I30: =+W7 | J30: =+X7
A31: =+G8 | B31: =K8 | C31: =+L8 | D31: =+M8 | E31: =+T8 | F31: =+U8 | G31: =+VLOOKUP(T8,'BBDD ACREEDORES'!$B:$C,2,0) | H31: =+N8 | I31: =+W8 | J31: =+X8
A32: =+G9 | B32: =K9 | C32: =+L9 | D32: =+M9 | E32: =+T9 | F32: =+U9 | G32: =+VLOOKUP(T9,'BBDD ACREEDORES'!$B:$C,2,0) | H32: =+N9 | I32: =+W9 | J32: =+X9
A33: =+G10 | B33: =K10 | C33: =+L10 | D33: =+M10 | E33: =+T10 | F33: =+U10 | G33: =+VLOOKUP(T10,'BBDD ACREEDORES'!$B:$C,2,0) | H33: =+N10 | I33: =+W10 | J33: =+X10
A34: =+G11 | B34: =K11 | C34: =+L11 | D34: =+M11 | E34: =+T11 | F34: =+U11 | G34: =+VLOOKUP(T11,'BBDD ACREEDORES'!$B:$C,2,0) | H34: =+N11 | I34: =+W11 | J34: =+X11
A35: =+G12 | B35: =K12 | C35: =+L12 | D35: =+M12 | E35: =+T12 | F35: =+U12 | G35: =+VLOOKUP(T12,'BBDD ACREEDORES'!$B:$C,2,0) | H35: =+N12 | I35: =+W12 | J35: =+X12
A36: =+G13 | B36: =K13 | C36: =+L13 | D36: =+M13 | E36: =+T13 | F36: =+U13 | G36: =+VLOOKUP(T13,'BBDD ACREEDORES'!$B:$C,2,0) | H36: =+N13 | I36: =+W13 | J36: =+X13
A37: =+G14 | B37: =K14 | C37: =+L14 | D37: =+M14 | E37: =+T14 | F37: =+U14 | G37: =+VLOOKUP(T14,'BBDD ACREEDORES'!$B:$C,2,0) | H37: =+N14 | I37: =+W14 | J37: =+X14
A38: =+G15 | B38: =K15 | C38: =+L15 | D38: =+M15 | E38: =+T15 | F38: =+U15 | G38: =+VLOOKUP(T15,'BBDD ACREEDORES'!$B:$C,2,0) | H38: =+N15 | I38: =+W15 | J38: =+X15
A39: =+G16 | B39: =K16 | C39: =+L16 | D39: =+M16 | E39: =+T16 | F39: =+U16 | G39: =+VLOOKUP(T16,'BBDD ACREEDORES'!$B:$C,2,0) | H39: =+N16 | I39: =+W16 | J39: =+X16
A40: =+G17 | B40: =K17 | C40: =+L17 | D40: =+M17 | E40: =+T17 | F40: =+U17 | G40: =+VLOOKUP(T17,'BBDD ACREEDORES'!$B:$C,2,0) | H40: =+N17 | I40: =+W17 | J40: =+X17
A41: =+G18 | B41: =K18 | C41: =+L18 | D41: =+M18 | E41: =+T18 | F41: =+U18 | G41: =+VLOOKUP(T18,'BBDD ACREEDORES'!$B:$C,2,0) | H41: =+N18 | I41: =+W18 | J41: =+X18

Sheet Consultas  Victoria
A1: Activity | B1: Estado de la tarea | C1: Fecha Creación del caso hasta | D1: Current User - Full Name | E1: Nemotécnico | F1: Rut Acreedor | G1: Razón Social Acreedor | H1: Rut Deudor | I1: Razón Social Deudor | J1: Tipo de Disconformidad | K1: Monto bruto instrucción de pago | L1: Saldo Pendiente (Neto) | M1: Número de Disconformidad | N1: Fecha de Vencimiento Desde | O1: ¿Disconformidad Abierta por? | P1: Tipo de Disconformidad | Q1: En Espera de Ejecución | R1: Mes | S1: Plazo (10 Dias hab) | T1: N° Acreedor | U1: N° factura | V1: Emisión | W1: Emisión
A2: Esperar Para Avanzar - Realizar Seguimiento Deudor - Realizar Seguimiento Acreedor - Cerrar Anticipado - Gestionar en Plazo de Regulación - Cancelar - Esperar Movimientos | B2: A tiempo - A tiempo - A tiempo - A tiempo - En riesgo - A tiempo - A tiempo | C2: 45970.098 | D2: - Sin Asignar | E2: [DISC_349677][P][SEN_[TEE_][May24][L][V01]][7626493] | F2: 77271459 | G2: ALTO BELLAVISTA SPA | H2: 77316204 | I2: CGE COMERCIALIZADORA SPA | J2: Pago | K2: 12171 | L2: 10228 | M2: DISC_349677 | N2: 45980.458 | O2: 45785 | P2: Acreedor | Q2: TEE_ | R2: =+MONTH(C2) | S2: =WORKDAY(C2,10) | T2: =+_xlfn.XLOOKUP(G2,'BBDD ACREEDORES'!$A:$A,'BBDD ACREEDORES'!$B:$B,"",0,1) | U2: 3395
D20: Rut | E20: Nemotécnico | F20: Razón Social Acreedor | G20: Monto bruto instrucción de pago | H20: Saldo Pendiente (Neto) | I20: Número de Disconformidad | J20: N° Acreedor | K20: N° factura
D21: =+_xlfn.XLOOKUP(J21,'BBDD ACREEDORES'!$B:$B,'BBDD ACREEDORES'!$C:$C,"",0,1) | E21: =+E2 | F21: =+G2 | G21: =+K2 | H21: =+L2 | I21: =+M2 | J21: =+T2 | K21: =+U2
D22: =+_xlfn.XLOOKUP(J22,'BBDD ACREEDORES'!$B:$B,'BBDD ACREEDORES'!$C:$C,"",0,1) | E22: =+E3 | F22: =+G3 | G22: =+K3 | H22: =+L3 | I22: =+M3 | J22: =+T3 | K22: =+U3
D23: =+_xlfn.XLOOKUP(J23,'BBDD ACREEDORES'!$B:$B,'BBDD ACREEDORES'!$C:$C,"",0,1) | E23: =+E4 | F23: =+G4 | G23: =+K4 | H23: =+L4 | I23: =+M4 | J23: =+T4 | K23: =+U4
D24: =+_xlfn.XLOOKUP(J24,'BBDD ACREEDORES'!$B:$B,'BBDD ACREEDORES'!$C:$C,"",0,1) | E24: =+E5 | F24: =+G5 | G24: =+K5 | H24: =+L5 | I24: =+M5 | J24: =+T5 | K24: =+U5
D25: =+_xlfn.XLOOKUP(J25,'BBDD ACREEDORES'!$B:$B,'BBDD ACREEDORES'!$C:$C,"",0,1) | E25: =+E6 | F25: =+G6 | G25: =+K6 | H25: =+L6 | I25: =+M6 | J25: =+T6 | K25: =+U6
D26: =+_xlfn.XLOOKUP(J26,'BBDD ACREEDORES'!$B:$B,'BBDD ACREEDORES'!$C:$C,"",0,1) | E26: =+E7 | F26: =+G7 | G26: =+K7 | H26: =+L7 | I26: =+M7 | J26: =+T7 | K26: =+U7
D27: =+_xlfn.XLOOKUP(J27,'BBDD ACREEDORES'!$B:$B,'BBDD ACREEDORES'!$C:$C,"",0,1) | E27: =+E8 | F27: =+G8 | G27: =+K8 | H27: =+L8 | I27: =+M8 | J27: =+T8 | K27: =+U8
D28: =+_xlfn.XLOOKUP(J28,'BBDD ACREEDORES'!$B:$B,'BBDD ACREEDORES'!$C:$C,"",0,1) | E28: =+E9 | F28: =+G9 | G28: =+K9 | H28: =+L9 | I28: =+M9 | J28: =+T9 | K28: =+U9
D29: =+_xlfn.XLOOKUP(J29,'BBDD ACREEDORES'!$B:$B,'BBDD ACREEDORES'!$C:$C,"",0,1) | E29: =+E10 | F29: =+G10 | G29: =+K10 | H29: =+L10 | I29: =+M10 | J29: =+T10 | K29: =+U10
D30: =+_xlfn.XLOOKUP(J30,'BBDD ACREEDORES'!$B:$B,'BBDD ACREEDORES'!$C:$C,"",0,1) | E30: =+E11 | F30: =+G11 | G30: =+K11 | H30: =+L11 | I30: =+M11 | J30: =+T11 | K30: =+U11
D31: =+_xlfn.XLOOKUP(J31,'BBDD ACREEDORES'!$B:$B,'BBDD ACREEDORES'!$C:$C,"",0,1) | E31: =+E12 | F31: =+G12 | G31: =+K12 | H31: =+L12 | I31: =+M12 | J31: =+T12 | K31: =+U12
D32: =+_xlfn.XLOOKUP(J32,'BBDD ACREEDORES'!$B:$B,'BBDD ACREEDORES'!$C:$C,"",0,1) | E32: =+E13 | F32: =+G13 | G32: =+K13 | H32: =+L13 | I32: =+M13 | J32: =+T13 | K32: =+U13
D33: =+_xlfn.XLOOKUP(J33,'BBDD ACREEDORES'!$B:$B,'BBDD ACREEDORES'!$C:$C,"",0,1) | E33: =+E14 | F33: =+G14 | G33: =+K14 | H33: =+L14 | I33: =+M14 | J33: =+T14 | K33: =+U14

Sheet Hoja2
M4: Número de Disconformidad | N4: Fecha de Vencimiento Desde | O4: ¿Disconformidad Abierta por? | P4: Tipo de Disconformidad | Q4: En Espera de Ejecución | R4: Mes | S4: Plazo | T4: N° Acreedor | U4: N° factura
M5: DISC_114242 | N5: 45159 | O5: Acreedor | P5: Pago | Q5: No | R5: 3 | S5: 45372 | T5: 1025974 | U5: 8938
B22: coordinador
B36: buscar si llego la factura
B37: Rut Acreedor | C37: Razón Social Acreedor | D37: N° Acreedor | E37: N° factura
B38: 768372721 | C38: Hidroconfianza SpA | D38: 1028470 | E38: 128 | F38: revisar si llego la factura
B39: 76985186 | C39: Blu Solar SpA | D39: 1028412 | E39: 729 | F39: comprobantes de pago | G39: se pagaron 2 facturas (1305+43727=45.032)
B40: 76985186 | C40: Blu Solar SpA | D40: 1028412 | E40: 787 | F40: comprobantes de pago | G40: se pagaron 2 facturas (1305+43727=45.032)
B41: 70287900 | C41: Cooperativa de Abastecimiento de Energía Eléctrica Curico LTDA. | D41: 1007022 | E41: 353409 | F41: comprobantes de pago | G41: se pagaron 2 facturas (19+3929=3.948)
